Workbook

Sheet données
A1: Tableau des charges fixes
B3: par mois | C3: par an
A4: Loyer du local | B4: 1000 | C4: =B4*12 -> 12000
A5: Mobilier / aménagement cuisines | B5: =C5/12 -> 250 | C5: 3000
A6: Factures eau et énergie | B6: 200 | C6: =B6*12 -> 2400
A7: Entretien des locaux | B7: 100 | C7: =B7*12 -> 1200
A8: Publicité | B8: =C8/12 -> 66.666667 | C8: 800
A9: Prime d'assurance | B9: =C9/12 -> 100 | C9: 1200
A10: Emprunt bancaire | B10: 250 | C10: =B10*12 -> 3000
A11: Personnel (2 x SMIC, 1 365 €/mois) | B11: 2730 | C11: =B11*12 -> 32760
A12: TOTAL | B12: =SUM(B4:B11) -> 4696.6667 | C12: =SUM(C4:C11) -> 56360
A13: Légende : cellules bleues = valeurs saisies (modifiables) | cellules noires = calculs automatiques
A14: Tableau du prix des ventes
B15: prix de vente
A16: Menu 1 | B16: 15
A17: Menu 2 | B17: 25
A18: Menu 3 | B18: 35
A19: Boisson soft | B19: 3
A20: Boisson alcool | B20: 6
A21: Légende : cellules bleues = valeurs saisies (modifiables) | cellules noires = calculs automatiques
A22: Tableau des matières premières (coût par vente)
B23: coût matière
A24: Menu 1 | B24: 10
A25: Menu 2 | B25: 15
A26: Menu 3 | B26: 20
A27: Boisson soft | B27: 1
A28: Boisson alcool | B28: 2
A29: Légende : cellules bleues = valeurs saisies (modifiables) | cellules noires = calculs automatiques
A30: Taux de taxes et impôts (sur le prix de vente)
A31: Taux taxe menu | B31: 0.1
A32: Taux taxe boisson | B32: 0.2
A34: Montant de la taxe pour 1 vente
B35: taxe / vente
A36: Menu 1 | B36: =B16*$B$31 -> 1.5
A37: Menu 2 | B37: =B17*$B$31 -> 2.5
A38: Menu 3 | B38: =B18*$B$31 -> 3.5
A39: Boisson soft | B39: =B19*$B$32 -> 0.6
A40: Boisson alcool | B40: =B20*$B$32 -> 1.2
A41: Légende : cellules bleues = valeurs saisies (modifiables) | cellules noires = calculs automatiques
A43: Tableau répartition des ventes sur 2016
...

Sheet bilan 2016
A1: Bilan 2016
B2: Jan | C2: Fév | D2: Mars | E2: Avr | F2: Mai | G2: Juin | H2: Juil | I2: Août | J2: Sept | K2: Oct | L2: Nov | M2: Déc | N2: TOTAL
A3: CA Menu 1 | B3: =données!B45*données!$B$16 -> 1950 | C3: =données!C45*données!$B$16 -> 1050 | D3: =données!D45*données!$B$16 -> 3750 | E3: =données!E45*données!$B$16 -> 3300 | F3: =données!F45*données!$B$16 -> 1050 | G3: =données!G45*données!$B$16 -> 2250 | H3: =données!H45*données!$B$16 -> 1500 | I3: =données!I45*données!$B$16 -> 3600 | ... M3: =données!M45*données!$B$16 -> 1950 | N3: =SUM(B3:M3) -> 23850
A4: CA Menu 2 | B4: =données!B46*données!$B$17 -> 2250 | C4: =données!C46*données!$B$17 -> 2250 | D4: =données!D46*données!$B$17 -> 5250 | E4: =données!E46*données!$B$17 -> 2000 | F4: =données!F46*données!$B$17 -> 4000 | G4: =données!G46*données!$B$17 -> 3500 | H4: =données!H46*données!$B$17 -> 5000 | I4: =données!I46*données!$B$17 -> 3750 | ... M4: =données!M46*données!$B$17 -> 1500 | N4: =SUM(B4:M4) -> 41750
A5: CA Menu 3 | B5: =données!B47*données!$B$18 -> 2800 | C5: =données!C47*données!$B$18 -> 4550 | D5: =données!D47*données!$B$18 -> 6300 | E5: =données!E47*données!$B$18 -> 3150 | F5: =données!F47*données!$B$18 -> 7350 | G5: =données!G47*données!$B$18 -> 8750 | H5: =données!H47*données!$B$18 -> 2450 | I5: =données!I47*données!$B$18 -> 4900 | ... M5: =données!M47*données!$B$18 -> 4550 | N5: =SUM(B5:M5) -> 56350
A6: CA Soft | B6: =données!B48*données!$B$19 -> 390 | C6: =données!C48*données!$B$19 -> 750 | D6: =données!D48*données!$B$19 -> 180 | E6: =données!E48*données!$B$19 -> 570 | F6: =données!F48*données!$B$19 -> 750 | G6: =données!G48*données!$B$19 -> 390 | H6: =données!H48*données!$B$19 -> 510 | I6: =données!I48*données!$B$19 -> 330 | ... M6: =données!M48*données!$B$19 -> 180 | N6: =SUM(B6:M6) -> 5310
A7: CA alcool | B7: =données!B49*données!$B$20 -> 780 | C7: =données!C49*données!$B$20 -> 1080 | D7: =données!D49*données!$B$20 -> 840 | E7: =données!E49*données!$B$20 -> 1440 | F7: =données!F49*données!$B$20 -> 540 | G7: =données!G49*données!$B$20 -> 1080 | H7: =données!H49*données!$B$20 -> 1020 | I7: =données!I49*données!$B$20 -> 540 | ... M7: =données!M49*données!$B$20 -> 1140 | N7: =SUM(B7:M7) -> 11460
A8: TOTAL CA | B8: =SUM(B3:B7) -> 8170 | C8: =SUM(C3:C7) -> 9680 | D8: =SUM(D3:D7) -> 16320 | E8: =SUM(E3:E7) -> 10460 | F8: =SUM(F3:F7) -> 13690 | G8: =SUM(G3:G7) -> 15970 | H8: =SUM(H3:H7) -> 10480 | I8: =SUM(I3:I7) -> 13120 | ... N8: =SUM(N3:N7) -> 138720
A9: Charges fixes | B9: =données!$B$12 -> 4696.6667 | C9: =données!$B$12 -> 4696.6667 | D9: =données!$B$12 -> 4696.6667 | E9: =données!$B$12 -> 4696.6667 | F9: =données!$B$12 -> 4696.6667 | G9: =données!$B$12 -> 4696.6667 | H9: =données!$B$12 -> 4696.6667 | I9: =données!$B$12 -> 4696.6667 | ... M9: =données!$B$12 -> 4696.6667 | N9: =SUM(B9:M9) -> 56360
A10: Matière 1ère Menu 1 | B10: =données!B45*données!$B$24 -> 1300 | C10: =données!C45*données!$B$24 -> 700 | D10: =données!D45*données!$B$24 -> 2500 | E10: =données!E45*données!$B$24 -> 2200 | F10: =données!F45*données!$B$24 -> 700 | G10: =données!G45*données!$B$24 -> 1500 | H10: =données!H45*données!$B$24 -> 1000 | I10: =données!I45*données!$B$24 -> 2400 | ... M10: =données!M45*données!$B$24 -> 1300 | N10: =SUM(B10:M10) -> 15900
A11: Matière 1ère Menu 2 | B11: =données!B46*données!$B$25 -> 1350 | C11: =données!C46*données!$B$25 -> 1350 | D11: =données!D46*données!$B$25 -> 3150 | E11: =données!E46*données!$B$25 -> 1200 | F11: =données!F46*données!$B$25 -> 2400 | G11: =données!G46*données!$B$25 -> 2100 | H11: =données!H46*données!$B$25 -> 3000 | I11: =données!I46*données!$B$25 -> 2250 | ... M11: =données!M46*données!$B$25 -> 900 | N11: =SUM(B11:M11) -> 25050
A12: Matière 1ère Menu 3 | B12: =données!B47*données!$B$26 -> 1600 | C12: =données!C47*données!$B$26 -> 2600 | D12: =données!D47*données!$B$26 -> 3600 | E12: =données!E47*données!$B$26 -> 1800 | F12: =données!F47*données!$B$26 -> 4200 | G12: =données!G47*données!$B$26 -> 5000 | H12: =données!H47*données!$B$26 -> 1400 | I12: =données!I47*données!$B$26 -> 2800 | ... M12: =données!M47*données!$B$26 -> 2600 | N12: =SUM(B12:M12) -> 32200
A13: Matière 1ère Soft | B13: =données!B48*données!$B$27 -> 130 | C13: =données!C48*données!$B$27 -> 250 | D13: =données!D48*données!$B$27 -> 60 | E13: =données!E48*données!$B$27 -> 190 | F13: =données!F48*données!$B$27 -> 250 | G13: =données!G48*données!$B$27 -> 130 | H13: =données!H48*données!$B$27 -> 170 | I13: =données!I48*données!$B$27 -> 110 | ... M13: =données!M48*données!$B$27 -> 60 | N13: =SUM(B13:M13) -> 1770
A14: Matière 1ère alcool | B14: =données!B49*données!$B$28 -> 260 | C14: =données!C49*données!$B$28 -> 360 | D14: =données!D49*données!$B$28 -> 280 | E14: =données!E49*données!$B$28 -> 480 | F14: =données!F49*données!$B$28 -> 180 | G14: =données!G49*données!$B$28 -> 360 | H14: =données!H49*données!$B$28 -> 340 | I14: =données!I49*données!$B$28 -> 180 | ... M14: =données!M49*données!$B$28 -> 380 | N14: =SUM(B14:M14) -> 3820
A15: Taxe menu | B15: =(B3+B4+B5)*données!$B$31 -> 700 | C15: =(C3+C4+C5)*données!$B$31 -> 785 | D15: =(D3+D4+D5)*données!$B$31 -> 1530 | E15: =(E3+E4+E5)*données!$B$31 -> 845 | F15: =(F3+F4+F5)*données!$B$31 -> 1240 | G15: =(G3+G4+G5)*données!$B$31 -> 1450 | H15: =(H3+H4+H5)*données!$B$31 -> 895 | I15: =(I3+I4+I5)*données!$B$31 -> 1225 | ... M15: =(M3+M4+M5)*données!$B$31 -> 800 | N15: =SUM(B15:M15) -> 12195
A16: Taxe boisson | B16: =(B6+B7)*données!$B$32 -> 234 | C16: =(C6+C7)*données!$B$32 -> 366 | D16: =(D6+D7)*données!$B$32 -> 204 | E16: =(E6+E7)*données!$B$32 -> 402 | F16: =(F6+F7)*données!$B$32 -> 258 | G16: =(G6+G7)*données!$B$32 -> 294 | H16: =(H6+H7)*données!$B$32 -> 306 | I16: =(I6+I7)*données!$B$32 -> 174 | ... M16: =(M6+M7)*données!$B$32 -> 264 | N16: =SUM(B16:M16) -> 3354
A17: TOTAL charges variables | B17: =SUM(B10:B16) -> 5574 | C17: =SUM(C10:C16) -> 6411 | D17: =SUM(D10:D16) -> 11324 | E17: =SUM(E10:E16) -> 7117 | F17: =SUM(F10:F16) -> 9228 | G17: =SUM(G10:G16) -> 10834 | H17: =SUM(H10:H16) -> 7111 | I17: =SUM(I10:I16) -> 9139 | ... N17: =SUM(N10:N16) -> 94289
A18: TOTAL des charges | B18: =B9+B17 -> 10270.667 | C18: =C9+C17 -> 11107.667 | D18: =D9+D17 -> 16020.667 | E18: =E9+E17 -> 11813.667 | F18: =F9+F17 -> 13924.667 | G18: =G9+G17 -> 15530.667 | H18: =H9+H17 -> 11807.667 | I18: =I9+I17 -> 13835.667 | ... N18: =N9+N17 -> 150649
A19: TOTAL des coûts | B19: =B18 -> 10270.667 | C19: =C18 -> 11107.667 | D19: =D18 -> 16020.667 | E19: =E18 -> 11813.667 | F19: =F18 -> 13924.667 | G19: =G18 -> 15530.667 | H19: =H18 -> 11807.667 | I19: =I18 -> 13835.667 | ... N19: =N18 -> 150649
A20: Résultat | B20: =B8-B19 -> -2100.6667 | C20: =C8-C19 -> -1427.6667 | D20: =D8-D19 -> 299.33333 | E20: =E8-E19 -> -1353.6667 | F20: =F8-F19 -> -234.66667 | G20: =G8-G19 -> 439.33333 | H20: =H8-H19 -> -1327.6667 | I20: =I8-I19 -> -715.66667 | ... N20: =N8-N19 -> -11929
